[2022-02-06 15:09:11,999] {taskinstance.py:1032} INFO - Dependencies all met for <TaskInstance: data_ingestion_gcs_dag.download_dataset_task scheduled__2021-04-02T06:00:00+00:00 [queued]>
[2022-02-06 15:09:12,072] {taskinstance.py:1032} INFO - Dependencies all met for <TaskInstance: data_ingestion_gcs_dag.download_dataset_task scheduled__2021-04-02T06:00:00+00:00 [queued]>
[2022-02-06 15:09:12,074] {taskinstance.py:1238} INFO - 
--------------------------------------------------------------------------------
[2022-02-06 15:09:12,081] {taskinstance.py:1239} INFO - Starting attempt 1 of 2
[2022-02-06 15:09:12,087] {taskinstance.py:1240} INFO - 
--------------------------------------------------------------------------------
[2022-02-06 15:09:12,182] {taskinstance.py:1259} INFO - Executing <Task(BashOperator): download_dataset_task> on 2021-04-02 06:00:00+00:00
[2022-02-06 15:09:12,252] {standard_task_runner.py:52} INFO - Started process 3188 to run task
[2022-02-06 15:09:12,301] {standard_task_runner.py:76} INFO - Running: ['***', 'tasks', 'run', 'data_ingestion_gcs_dag', 'download_dataset_task', 'scheduled__2021-04-02T06:00:00+00:00', '--job-id', '165', '--raw', '--subdir', 'DAGS_FOLDER/data_ingestion_gcs_dags_hw.py', '--cfg-path', '/tmp/tmp7sk9fxop', '--error-file', '/tmp/tmpvhkhbkkd']
[2022-02-06 15:09:12,316] {standard_task_runner.py:77} INFO - Job 165: Subtask download_dataset_task
[2022-02-06 15:09:13,196] {logging_mixin.py:109} INFO - Running <TaskInstance: data_ingestion_gcs_dag.download_dataset_task scheduled__2021-04-02T06:00:00+00:00 [running]> on host 6aa22590a839
[2022-02-06 15:09:13,708] {warnings.py:110} WARNING - /home/***/.local/lib/python3.7/site-packages/***/utils/context.py:152: AirflowContextDeprecationWarning: Accessing 'execution_date' from the template is deprecated and will be removed in a future version. Please use 'data_interval_start' or 'logical_date' instead.
  warnings.warn(_create_deprecation_warning(key, self._deprecation_replacements[key]))

[2022-02-06 15:09:13,760] {taskinstance.py:1426} INFO - Exporting the following env vars:
AIRFLOW_CTX_DAG_OWNER=***
AIRFLOW_CTX_DAG_ID=data_ingestion_gcs_dag
AIRFLOW_CTX_TASK_ID=download_dataset_task
AIRFLOW_CTX_EXECUTION_DATE=2021-04-02T06:00:00+00:00
AIRFLOW_CTX_DAG_RUN_ID=scheduled__2021-04-02T06:00:00+00:00
[2022-02-06 15:09:13,774] {subprocess.py:62} INFO - Tmp dir root location: 
 /tmp
[2022-02-06 15:09:13,780] {subprocess.py:74} INFO - Running command: ['bash', '-c', 'curl -sS https://s3.amazonaws.com/nyc-tlc/trip+data/yellow_tripdata_2021-04.csv > /opt/***/yellow_tripdata_2021-04.csv']
[2022-02-06 15:09:13,852] {subprocess.py:85} INFO - Output:
[2022-02-06 16:11:16,736] {subprocess.py:89} INFO - curl: (18) transfer closed with 11019243 bytes remaining to read
[2022-02-06 16:11:19,362] {subprocess.py:93} INFO - Command exited with return code 18
[2022-02-06 16:11:44,991] {taskinstance.py:1700} ERROR - Task failed with exception
Traceback (most recent call last):
  File "/home/airflow/.local/lib/python3.7/site-packages/airflow/models/taskinstance.py", line 1329, in _run_raw_task
    self._execute_task_with_callbacks(context)
  File "/home/airflow/.local/lib/python3.7/site-packages/airflow/models/taskinstance.py", line 1455, in _execute_task_with_callbacks
    result = self._execute_task(context, self.task)
  File "/home/airflow/.local/lib/python3.7/site-packages/airflow/models/taskinstance.py", line 1511, in _execute_task
    result = execute_callable(context=context)
  File "/home/airflow/.local/lib/python3.7/site-packages/airflow/operators/bash.py", line 188, in execute
    f'Bash command failed. The command returned a non-zero exit code {result.exit_code}.'
airflow.exceptions.AirflowException: Bash command failed. The command returned a non-zero exit code 18.
[2022-02-06 16:11:50,284] {taskinstance.py:1277} INFO - Marking task as UP_FOR_RETRY. dag_id=data_ingestion_gcs_dag, task_id=download_dataset_task, execution_date=20210402T060000, start_date=20220206T150912, end_date=20220206T161147
[2022-02-06 16:11:55,948] {standard_task_runner.py:92} ERROR - Failed to execute job 165 for task download_dataset_task
Traceback (most recent call last):
  File "/home/airflow/.local/lib/python3.7/site-packages/airflow/task/task_runner/standard_task_runner.py", line 85, in _start_by_fork
    args.func(args, dag=self.dag)
  File "/home/airflow/.local/lib/python3.7/site-packages/airflow/cli/cli_parser.py", line 48, in command
    return func(*args, **kwargs)
  File "/home/airflow/.local/lib/python3.7/site-packages/airflow/utils/cli.py", line 92, in wrapper
    return f(*args, **kwargs)
  File "/home/airflow/.local/lib/python3.7/site-packages/airflow/cli/commands/task_command.py", line 298, in task_run
    _run_task_by_selected_method(args, dag, ti)
  File "/home/airflow/.local/lib/python3.7/site-packages/airflow/cli/commands/task_command.py", line 107, in _run_task_by_selected_method
    _run_raw_task(args, ti)
  File "/home/airflow/.local/lib/python3.7/site-packages/airflow/cli/commands/task_command.py", line 184, in _run_raw_task
    error_file=args.error_file,
  File "/home/airflow/.local/lib/python3.7/site-packages/airflow/utils/session.py", line 70, in wrapper
    return func(*args, session=session, **kwargs)
  File "/home/airflow/.local/lib/python3.7/site-packages/airflow/models/taskinstance.py", line 1329, in _run_raw_task
    self._execute_task_with_callbacks(context)
  File "/home/airflow/.local/lib/python3.7/site-packages/airflow/models/taskinstance.py", line 1455, in _execute_task_with_callbacks
    result = self._execute_task(context, self.task)
  File "/home/airflow/.local/lib/python3.7/site-packages/airflow/models/taskinstance.py", line 1511, in _execute_task
    result = execute_callable(context=context)
  File "/home/airflow/.local/lib/python3.7/site-packages/airflow/operators/bash.py", line 188, in execute
    f'Bash command failed. The command returned a non-zero exit code {result.exit_code}.'
airflow.exceptions.AirflowException: Bash command failed. The command returned a non-zero exit code 18.
[2022-02-06 16:11:56,721] {local_task_job.py:212} WARNING - State of this instance has been externally set to up_for_retry. Terminating instance.
[2022-02-06 16:11:57,361] {process_utils.py:124} INFO - Sending Signals.SIGTERM to group 3188. PIDs of all processes in the group: [3188]
[2022-02-06 16:11:57,559] {process_utils.py:75} INFO - Sending the signal Signals.SIGTERM to group 3188
[2022-02-06 16:11:59,858] {process_utils.py:70} INFO - Process psutil.Process(pid=3188, status='terminated', exitcode=1, started='15:09:11') (3188) terminated with exit code 1
