[2022-02-05 20:13:51,185] {taskinstance.py:1032} INFO - Dependencies all met for <TaskInstance: data_ingestion_gcs_dag.download_dataset_task scheduled__2019-08-02T06:00:00+00:00 [queued]>
[2022-02-05 20:13:51,307] {taskinstance.py:1032} INFO - Dependencies all met for <TaskInstance: data_ingestion_gcs_dag.download_dataset_task scheduled__2019-08-02T06:00:00+00:00 [queued]>
[2022-02-05 20:13:51,312] {taskinstance.py:1238} INFO - 
--------------------------------------------------------------------------------
[2022-02-05 20:13:51,316] {taskinstance.py:1239} INFO - Starting attempt 1 of 2
[2022-02-05 20:13:51,318] {taskinstance.py:1240} INFO - 
--------------------------------------------------------------------------------
[2022-02-05 20:13:51,424] {taskinstance.py:1259} INFO - Executing <Task(BashOperator): download_dataset_task> on 2019-08-02 06:00:00+00:00
[2022-02-05 20:13:51,501] {standard_task_runner.py:52} INFO - Started process 1750 to run task
[2022-02-05 20:13:51,546] {standard_task_runner.py:76} INFO - Running: ['***', 'tasks', 'run', 'data_ingestion_gcs_dag', 'download_dataset_task', 'scheduled__2019-08-02T06:00:00+00:00', '--job-id', '118', '--raw', '--subdir', 'DAGS_FOLDER/data_ingestion_gcs_dags_hw.py', '--cfg-path', '/tmp/tmputzpk975', '--error-file', '/tmp/tmp0g24_8lk']
[2022-02-05 20:13:51,585] {standard_task_runner.py:77} INFO - Job 118: Subtask download_dataset_task
[2022-02-05 20:13:52,139] {logging_mixin.py:109} INFO - Running <TaskInstance: data_ingestion_gcs_dag.download_dataset_task scheduled__2019-08-02T06:00:00+00:00 [running]> on host 6aa22590a839
[2022-02-05 20:13:53,598] {warnings.py:110} WARNING - /home/***/.local/lib/python3.7/site-packages/***/utils/context.py:152: AirflowContextDeprecationWarning: Accessing 'execution_date' from the template is deprecated and will be removed in a future version. Please use 'data_interval_start' or 'logical_date' instead.
  warnings.warn(_create_deprecation_warning(key, self._deprecation_replacements[key]))

[2022-02-05 20:13:53,708] {taskinstance.py:1426} INFO - Exporting the following env vars:
AIRFLOW_CTX_DAG_OWNER=***
AIRFLOW_CTX_DAG_ID=data_ingestion_gcs_dag
AIRFLOW_CTX_TASK_ID=download_dataset_task
AIRFLOW_CTX_EXECUTION_DATE=2019-08-02T06:00:00+00:00
AIRFLOW_CTX_DAG_RUN_ID=scheduled__2019-08-02T06:00:00+00:00
[2022-02-05 20:13:53,723] {subprocess.py:62} INFO - Tmp dir root location: 
 /tmp
[2022-02-05 20:13:53,738] {subprocess.py:74} INFO - Running command: ['bash', '-c', 'curl -sS https://s3.amazonaws.com/nyc-tlc/trip+data/yellow_tripdata_2019-08.csv > /opt/***/yellow_tripdata_2019-08.csv']
[2022-02-05 20:13:53,925] {subprocess.py:85} INFO - Output:
[2022-02-05 20:22:34,974] {local_task_job.py:212} WARNING - State of this instance has been externally set to up_for_retry. Terminating instance.
[2022-02-05 20:22:35,117] {process_utils.py:124} INFO - Sending Signals.SIGTERM to group 1750. PIDs of all processes in the group: [1751, 1752, 1750]
[2022-02-05 20:22:35,315] {process_utils.py:75} INFO - Sending the signal Signals.SIGTERM to group 1750
[2022-02-05 20:22:35,379] {taskinstance.py:1408} ERROR - Received SIGTERM. Terminating subprocesses.
[2022-02-05 20:22:35,489] {subprocess.py:99} INFO - Sending SIGTERM signal to process group
[2022-02-05 20:22:36,471] {process_utils.py:70} INFO - Process psutil.Process(pid=1752, status='terminated', started='20:13:53') (1752) terminated with exit code None
[2022-02-05 20:22:37,151] {taskinstance.py:1700} ERROR - Task failed with exception
Traceback (most recent call last):
  File "/home/airflow/.local/lib/python3.7/site-packages/airflow/models/taskinstance.py", line 1329, in _run_raw_task
    self._execute_task_with_callbacks(context)
  File "/home/airflow/.local/lib/python3.7/site-packages/airflow/models/taskinstance.py", line 1455, in _execute_task_with_callbacks
    result = self._execute_task(context, self.task)
  File "/home/airflow/.local/lib/python3.7/site-packages/airflow/models/taskinstance.py", line 1511, in _execute_task
    result = execute_callable(context=context)
  File "/home/airflow/.local/lib/python3.7/site-packages/airflow/operators/bash.py", line 182, in execute
    cwd=self.cwd,
  File "/home/airflow/.local/lib/python3.7/site-packages/airflow/hooks/subprocess.py", line 87, in run_command
    for raw_line in iter(self.sub_process.stdout.readline, b''):
  File "/home/airflow/.local/lib/python3.7/site-packages/airflow/models/taskinstance.py", line 1410, in signal_handler
    raise AirflowException("Task received SIGTERM signal")
airflow.exceptions.AirflowException: Task received SIGTERM signal
[2022-02-05 20:22:37,190] {taskinstance.py:1277} INFO - Marking task as FAILED. dag_id=data_ingestion_gcs_dag, task_id=download_dataset_task, execution_date=20190802T060000, start_date=20220205T201351, end_date=20220205T202237
[2022-02-05 20:22:37,262] {standard_task_runner.py:92} ERROR - Failed to execute job 118 for task download_dataset_task
Traceback (most recent call last):
  File "/home/airflow/.local/lib/python3.7/site-packages/airflow/task/task_runner/standard_task_runner.py", line 85, in _start_by_fork
    args.func(args, dag=self.dag)
  File "/home/airflow/.local/lib/python3.7/site-packages/airflow/cli/cli_parser.py", line 48, in command
    return func(*args, **kwargs)
  File "/home/airflow/.local/lib/python3.7/site-packages/airflow/utils/cli.py", line 92, in wrapper
    return f(*args, **kwargs)
  File "/home/airflow/.local/lib/python3.7/site-packages/airflow/cli/commands/task_command.py", line 298, in task_run
    _run_task_by_selected_method(args, dag, ti)
  File "/home/airflow/.local/lib/python3.7/site-packages/airflow/cli/commands/task_command.py", line 107, in _run_task_by_selected_method
    _run_raw_task(args, ti)
  File "/home/airflow/.local/lib/python3.7/site-packages/airflow/cli/commands/task_command.py", line 184, in _run_raw_task
    error_file=args.error_file,
  File "/home/airflow/.local/lib/python3.7/site-packages/airflow/utils/session.py", line 70, in wrapper
    return func(*args, session=session, **kwargs)
  File "/home/airflow/.local/lib/python3.7/site-packages/airflow/models/taskinstance.py", line 1329, in _run_raw_task
    self._execute_task_with_callbacks(context)
  File "/home/airflow/.local/lib/python3.7/site-packages/airflow/models/taskinstance.py", line 1455, in _execute_task_with_callbacks
    result = self._execute_task(context, self.task)
  File "/home/airflow/.local/lib/python3.7/site-packages/airflow/models/taskinstance.py", line 1511, in _execute_task
    result = execute_callable(context=context)
  File "/home/airflow/.local/lib/python3.7/site-packages/airflow/operators/bash.py", line 182, in execute
    cwd=self.cwd,
  File "/home/airflow/.local/lib/python3.7/site-packages/airflow/hooks/subprocess.py", line 87, in run_command
    for raw_line in iter(self.sub_process.stdout.readline, b''):
  File "/home/airflow/.local/lib/python3.7/site-packages/airflow/models/taskinstance.py", line 1410, in signal_handler
    raise AirflowException("Task received SIGTERM signal")
airflow.exceptions.AirflowException: Task received SIGTERM signal
[2022-02-05 20:22:37,330] {process_utils.py:70} INFO - Process psutil.Process(pid=1750, status='terminated', exitcode=1, started='20:13:50') (1750) terminated with exit code 1
[2022-02-05 20:22:37,332] {process_utils.py:70} INFO - Process psutil.Process(pid=1751, status='terminated', started='20:13:53') (1751) terminated with exit code None
