[2022-02-06 11:06:57,609] {taskinstance.py:1032} INFO - Dependencies all met for <TaskInstance: data_ingestion_gcs_dag.download_dataset_task scheduled__2020-06-02T06:00:00+00:00 [queued]>
[2022-02-06 11:06:57,664] {taskinstance.py:1032} INFO - Dependencies all met for <TaskInstance: data_ingestion_gcs_dag.download_dataset_task scheduled__2020-06-02T06:00:00+00:00 [queued]>
[2022-02-06 11:06:57,667] {taskinstance.py:1238} INFO - 
--------------------------------------------------------------------------------
[2022-02-06 11:06:57,669] {taskinstance.py:1239} INFO - Starting attempt 1 of 2
[2022-02-06 11:06:57,671] {taskinstance.py:1240} INFO - 
--------------------------------------------------------------------------------
[2022-02-06 11:06:57,741] {taskinstance.py:1259} INFO - Executing <Task(BashOperator): download_dataset_task> on 2020-06-02 06:00:00+00:00
[2022-02-06 11:06:57,778] {standard_task_runner.py:52} INFO - Started process 2624 to run task
[2022-02-06 11:06:57,817] {standard_task_runner.py:76} INFO - Running: ['***', 'tasks', 'run', 'data_ingestion_gcs_dag', 'download_dataset_task', 'scheduled__2020-06-02T06:00:00+00:00', '--job-id', '134', '--raw', '--subdir', 'DAGS_FOLDER/data_ingestion_gcs_dags_hw.py', '--cfg-path', '/tmp/tmpegon1esj', '--error-file', '/tmp/tmpt6imzjda']
[2022-02-06 11:06:57,828] {standard_task_runner.py:77} INFO - Job 134: Subtask download_dataset_task
[2022-02-06 11:06:58,128] {logging_mixin.py:109} INFO - Running <TaskInstance: data_ingestion_gcs_dag.download_dataset_task scheduled__2020-06-02T06:00:00+00:00 [running]> on host 6aa22590a839
[2022-02-06 11:06:58,460] {warnings.py:110} WARNING - /home/***/.local/lib/python3.7/site-packages/***/utils/context.py:152: AirflowContextDeprecationWarning: Accessing 'execution_date' from the template is deprecated and will be removed in a future version. Please use 'data_interval_start' or 'logical_date' instead.
  warnings.warn(_create_deprecation_warning(key, self._deprecation_replacements[key]))

[2022-02-06 11:06:58,664] {taskinstance.py:1426} INFO - Exporting the following env vars:
AIRFLOW_CTX_DAG_OWNER=***
AIRFLOW_CTX_DAG_ID=data_ingestion_gcs_dag
AIRFLOW_CTX_TASK_ID=download_dataset_task
AIRFLOW_CTX_EXECUTION_DATE=2020-06-02T06:00:00+00:00
AIRFLOW_CTX_DAG_RUN_ID=scheduled__2020-06-02T06:00:00+00:00
[2022-02-06 11:06:58,691] {subprocess.py:62} INFO - Tmp dir root location: 
 /tmp
[2022-02-06 11:06:58,734] {subprocess.py:74} INFO - Running command: ['bash', '-c', 'curl -sS https://s3.amazonaws.com/nyc-tlc/trip+data/yellow_tripdata_2020-06.csv > /opt/***/yellow_tripdata_2020-06.csv']
[2022-02-06 11:06:58,875] {subprocess.py:85} INFO - Output:
[2022-02-06 11:20:49,541] {local_task_job.py:212} WARNING - State of this instance has been externally set to up_for_retry. Terminating instance.
[2022-02-06 11:20:49,656] {process_utils.py:124} INFO - Sending Signals.SIGTERM to group 2624. PIDs of all processes in the group: [2626, 2628, 2624]
[2022-02-06 11:20:49,684] {process_utils.py:75} INFO - Sending the signal Signals.SIGTERM to group 2624
[2022-02-06 11:20:49,690] {taskinstance.py:1408} ERROR - Received SIGTERM. Terminating subprocesses.
[2022-02-06 11:20:49,703] {subprocess.py:99} INFO - Sending SIGTERM signal to process group
[2022-02-06 11:20:50,061] {process_utils.py:70} INFO - Process psutil.Process(pid=2628, status='terminated', started='11:06:58') (2628) terminated with exit code None
[2022-02-06 11:20:50,560] {taskinstance.py:1700} ERROR - Task failed with exception
Traceback (most recent call last):
  File "/home/airflow/.local/lib/python3.7/site-packages/airflow/models/taskinstance.py", line 1329, in _run_raw_task
    self._execute_task_with_callbacks(context)
  File "/home/airflow/.local/lib/python3.7/site-packages/airflow/models/taskinstance.py", line 1455, in _execute_task_with_callbacks
    result = self._execute_task(context, self.task)
  File "/home/airflow/.local/lib/python3.7/site-packages/airflow/models/taskinstance.py", line 1511, in _execute_task
    result = execute_callable(context=context)
  File "/home/airflow/.local/lib/python3.7/site-packages/airflow/operators/bash.py", line 182, in execute
    cwd=self.cwd,
  File "/home/airflow/.local/lib/python3.7/site-packages/airflow/hooks/subprocess.py", line 87, in run_command
    for raw_line in iter(self.sub_process.stdout.readline, b''):
  File "/home/airflow/.local/lib/python3.7/site-packages/airflow/models/taskinstance.py", line 1410, in signal_handler
    raise AirflowException("Task received SIGTERM signal")
airflow.exceptions.AirflowException: Task received SIGTERM signal
[2022-02-06 11:20:50,783] {taskinstance.py:1277} INFO - Marking task as FAILED. dag_id=data_ingestion_gcs_dag, task_id=download_dataset_task, execution_date=20200602T060000, start_date=20220206T110657, end_date=20220206T112050
[2022-02-06 11:20:50,919] {standard_task_runner.py:92} ERROR - Failed to execute job 134 for task download_dataset_task
Traceback (most recent call last):
  File "/home/airflow/.local/lib/python3.7/site-packages/airflow/task/task_runner/standard_task_runner.py", line 85, in _start_by_fork
    args.func(args, dag=self.dag)
  File "/home/airflow/.local/lib/python3.7/site-packages/airflow/cli/cli_parser.py", line 48, in command
    return func(*args, **kwargs)
  File "/home/airflow/.local/lib/python3.7/site-packages/airflow/utils/cli.py", line 92, in wrapper
    return f(*args, **kwargs)
  File "/home/airflow/.local/lib/python3.7/site-packages/airflow/cli/commands/task_command.py", line 298, in task_run
    _run_task_by_selected_method(args, dag, ti)
  File "/home/airflow/.local/lib/python3.7/site-packages/airflow/cli/commands/task_command.py", line 107, in _run_task_by_selected_method
    _run_raw_task(args, ti)
  File "/home/airflow/.local/lib/python3.7/site-packages/airflow/cli/commands/task_command.py", line 184, in _run_raw_task
    error_file=args.error_file,
  File "/home/airflow/.local/lib/python3.7/site-packages/airflow/utils/session.py", line 70, in wrapper
    return func(*args, session=session, **kwargs)
  File "/home/airflow/.local/lib/python3.7/site-packages/airflow/models/taskinstance.py", line 1329, in _run_raw_task
    self._execute_task_with_callbacks(context)
  File "/home/airflow/.local/lib/python3.7/site-packages/airflow/models/taskinstance.py", line 1455, in _execute_task_with_callbacks
    result = self._execute_task(context, self.task)
  File "/home/airflow/.local/lib/python3.7/site-packages/airflow/models/taskinstance.py", line 1511, in _execute_task
    result = execute_callable(context=context)
  File "/home/airflow/.local/lib/python3.7/site-packages/airflow/operators/bash.py", line 182, in execute
    cwd=self.cwd,
  File "/home/airflow/.local/lib/python3.7/site-packages/airflow/hooks/subprocess.py", line 87, in run_command
    for raw_line in iter(self.sub_process.stdout.readline, b''):
  File "/home/airflow/.local/lib/python3.7/site-packages/airflow/models/taskinstance.py", line 1410, in signal_handler
    raise AirflowException("Task received SIGTERM signal")
airflow.exceptions.AirflowException: Task received SIGTERM signal
[2022-02-06 11:20:51,192] {process_utils.py:70} INFO - Process psutil.Process(pid=2626, status='terminated', started='11:06:58') (2626) terminated with exit code None
[2022-02-06 11:20:51,194] {process_utils.py:70} INFO - Process psutil.Process(pid=2624, status='terminated', exitcode=1, started='11:06:57') (2624) terminated with exit code 1
