[2022-02-05 19:49:02,480] {taskinstance.py:1032} INFO - Dependencies all met for <TaskInstance: data_ingestion_gcs_dag.download_dataset_task scheduled__2019-03-02T06:00:00+00:00 [queued]>
[2022-02-05 19:49:02,540] {taskinstance.py:1032} INFO - Dependencies all met for <TaskInstance: data_ingestion_gcs_dag.download_dataset_task scheduled__2019-03-02T06:00:00+00:00 [queued]>
[2022-02-05 19:49:02,546] {taskinstance.py:1238} INFO - 
--------------------------------------------------------------------------------
[2022-02-05 19:49:02,559] {taskinstance.py:1239} INFO - Starting attempt 2 of 3
[2022-02-05 19:49:02,560] {taskinstance.py:1240} INFO - 
--------------------------------------------------------------------------------
[2022-02-05 19:49:02,671] {taskinstance.py:1259} INFO - Executing <Task(BashOperator): download_dataset_task> on 2019-03-02 06:00:00+00:00
[2022-02-05 19:49:02,773] {standard_task_runner.py:52} INFO - Started process 1579 to run task
[2022-02-05 19:49:02,880] {standard_task_runner.py:76} INFO - Running: ['***', 'tasks', 'run', 'data_ingestion_gcs_dag', 'download_dataset_task', 'scheduled__2019-03-02T06:00:00+00:00', '--job-id', '115', '--raw', '--subdir', 'DAGS_FOLDER/data_ingestion_gcs_dags_hw.py', '--cfg-path', '/tmp/tmpzk7h25lo', '--error-file', '/tmp/tmpghj2bx_4']
[2022-02-05 19:49:02,891] {standard_task_runner.py:77} INFO - Job 115: Subtask download_dataset_task
[2022-02-05 19:49:04,401] {logging_mixin.py:109} INFO - Running <TaskInstance: data_ingestion_gcs_dag.download_dataset_task scheduled__2019-03-02T06:00:00+00:00 [running]> on host 6aa22590a839
[2022-02-05 19:49:04,757] {warnings.py:110} WARNING - /home/***/.local/lib/python3.7/site-packages/***/utils/context.py:152: AirflowContextDeprecationWarning: Accessing 'execution_date' from the template is deprecated and will be removed in a future version. Please use 'data_interval_start' or 'logical_date' instead.
  warnings.warn(_create_deprecation_warning(key, self._deprecation_replacements[key]))

[2022-02-05 19:49:04,840] {taskinstance.py:1426} INFO - Exporting the following env vars:
AIRFLOW_CTX_DAG_OWNER=***
AIRFLOW_CTX_DAG_ID=data_ingestion_gcs_dag
AIRFLOW_CTX_TASK_ID=download_dataset_task
AIRFLOW_CTX_EXECUTION_DATE=2019-03-02T06:00:00+00:00
AIRFLOW_CTX_DAG_RUN_ID=scheduled__2019-03-02T06:00:00+00:00
[2022-02-05 19:49:04,851] {subprocess.py:62} INFO - Tmp dir root location: 
 /tmp
[2022-02-05 19:49:04,872] {subprocess.py:74} INFO - Running command: ['bash', '-c', 'curl -sS https://s3.amazonaws.com/nyc-tlc/trip+data/yellow_tripdata_2019-03.csv > /opt/***/yellow_tripdata_2019-03.csv']
[2022-02-05 19:49:05,115] {subprocess.py:85} INFO - Output:
[2022-02-05 20:13:28,327] {local_task_job.py:212} WARNING - State of this instance has been externally set to up_for_retry. Terminating instance.
[2022-02-05 20:13:29,033] {process_utils.py:124} INFO - Sending Signals.SIGTERM to group 1579. PIDs of all processes in the group: [1587, 1588, 1579]
[2022-02-05 20:13:29,055] {process_utils.py:75} INFO - Sending the signal Signals.SIGTERM to group 1579
[2022-02-05 20:13:29,304] {taskinstance.py:1408} ERROR - Received SIGTERM. Terminating subprocesses.
[2022-02-05 20:13:29,518] {subprocess.py:99} INFO - Sending SIGTERM signal to process group
[2022-02-05 20:13:30,482] {process_utils.py:70} INFO - Process psutil.Process(pid=1588, status='terminated', started='19:49:05') (1588) terminated with exit code None
[2022-02-05 20:13:31,455] {taskinstance.py:1700} ERROR - Task failed with exception
Traceback (most recent call last):
  File "/home/airflow/.local/lib/python3.7/site-packages/airflow/models/taskinstance.py", line 1329, in _run_raw_task
    self._execute_task_with_callbacks(context)
  File "/home/airflow/.local/lib/python3.7/site-packages/airflow/models/taskinstance.py", line 1455, in _execute_task_with_callbacks
    result = self._execute_task(context, self.task)
  File "/home/airflow/.local/lib/python3.7/site-packages/airflow/models/taskinstance.py", line 1511, in _execute_task
    result = execute_callable(context=context)
  File "/home/airflow/.local/lib/python3.7/site-packages/airflow/operators/bash.py", line 182, in execute
    cwd=self.cwd,
  File "/home/airflow/.local/lib/python3.7/site-packages/airflow/hooks/subprocess.py", line 87, in run_command
    for raw_line in iter(self.sub_process.stdout.readline, b''):
  File "/home/airflow/.local/lib/python3.7/site-packages/airflow/models/taskinstance.py", line 1410, in signal_handler
    raise AirflowException("Task received SIGTERM signal")
airflow.exceptions.AirflowException: Task received SIGTERM signal
[2022-02-05 20:13:31,705] {taskinstance.py:1277} INFO - Marking task as FAILED. dag_id=data_ingestion_gcs_dag, task_id=download_dataset_task, execution_date=20190302T060000, start_date=20220205T194902, end_date=20220205T201331
[2022-02-05 20:13:32,250] {standard_task_runner.py:92} ERROR - Failed to execute job 115 for task download_dataset_task
Traceback (most recent call last):
  File "/home/airflow/.local/lib/python3.7/site-packages/airflow/task/task_runner/standard_task_runner.py", line 85, in _start_by_fork
    args.func(args, dag=self.dag)
  File "/home/airflow/.local/lib/python3.7/site-packages/airflow/cli/cli_parser.py", line 48, in command
    return func(*args, **kwargs)
  File "/home/airflow/.local/lib/python3.7/site-packages/airflow/utils/cli.py", line 92, in wrapper
    return f(*args, **kwargs)
  File "/home/airflow/.local/lib/python3.7/site-packages/airflow/cli/commands/task_command.py", line 298, in task_run
    _run_task_by_selected_method(args, dag, ti)
  File "/home/airflow/.local/lib/python3.7/site-packages/airflow/cli/commands/task_command.py", line 107, in _run_task_by_selected_method
    _run_raw_task(args, ti)
  File "/home/airflow/.local/lib/python3.7/site-packages/airflow/cli/commands/task_command.py", line 184, in _run_raw_task
    error_file=args.error_file,
  File "/home/airflow/.local/lib/python3.7/site-packages/airflow/utils/session.py", line 70, in wrapper
    return func(*args, session=session, **kwargs)
  File "/home/airflow/.local/lib/python3.7/site-packages/airflow/models/taskinstance.py", line 1329, in _run_raw_task
    self._execute_task_with_callbacks(context)
  File "/home/airflow/.local/lib/python3.7/site-packages/airflow/models/taskinstance.py", line 1455, in _execute_task_with_callbacks
    result = self._execute_task(context, self.task)
  File "/home/airflow/.local/lib/python3.7/site-packages/airflow/models/taskinstance.py", line 1511, in _execute_task
    result = execute_callable(context=context)
  File "/home/airflow/.local/lib/python3.7/site-packages/airflow/operators/bash.py", line 182, in execute
    cwd=self.cwd,
  File "/home/airflow/.local/lib/python3.7/site-packages/airflow/hooks/subprocess.py", line 87, in run_command
    for raw_line in iter(self.sub_process.stdout.readline, b''):
  File "/home/airflow/.local/lib/python3.7/site-packages/airflow/models/taskinstance.py", line 1410, in signal_handler
    raise AirflowException("Task received SIGTERM signal")
airflow.exceptions.AirflowException: Task received SIGTERM signal
[2022-02-05 20:13:33,433] {process_utils.py:70} INFO - Process psutil.Process(pid=1587, status='terminated', started='19:49:05') (1587) terminated with exit code None
[2022-02-05 20:13:33,441] {process_utils.py:70} INFO - Process psutil.Process(pid=1579, status='terminated', exitcode=1, started='19:49:02') (1579) terminated with exit code 1
