[2022-02-06 22:46:18,420] {taskinstance.py:1032} INFO - Dependencies all met for <TaskInstance: data_ingestion_gcs_dag_yellow.download_dataset_task scheduled__2019-01-02T06:00:00+00:00 [queued]>
[2022-02-06 22:46:18,461] {taskinstance.py:1032} INFO - Dependencies all met for <TaskInstance: data_ingestion_gcs_dag_yellow.download_dataset_task scheduled__2019-01-02T06:00:00+00:00 [queued]>
[2022-02-06 22:46:18,463] {taskinstance.py:1238} INFO - 
--------------------------------------------------------------------------------
[2022-02-06 22:46:18,466] {taskinstance.py:1239} INFO - Starting attempt 1 of 2
[2022-02-06 22:46:18,468] {taskinstance.py:1240} INFO - 
--------------------------------------------------------------------------------
[2022-02-06 22:46:18,518] {taskinstance.py:1259} INFO - Executing <Task(BashOperator): download_dataset_task> on 2019-01-02 06:00:00+00:00
[2022-02-06 22:46:18,767] {standard_task_runner.py:52} INFO - Started process 3357 to run task
[2022-02-06 22:46:18,835] {standard_task_runner.py:76} INFO - Running: ['***', 'tasks', 'run', 'data_ingestion_gcs_dag_yellow', 'download_dataset_task', 'scheduled__2019-01-02T06:00:00+00:00', '--job-id', '245', '--raw', '--subdir', 'DAGS_FOLDER/data_ingestion_gcs_dags_yellowfull.py', '--cfg-path', '/tmp/tmpr5o4r33p', '--error-file', '/tmp/tmpn82tei9k']
[2022-02-06 22:46:18,844] {standard_task_runner.py:77} INFO - Job 245: Subtask download_dataset_task
[2022-02-06 22:46:20,664] {logging_mixin.py:109} INFO - Running <TaskInstance: data_ingestion_gcs_dag_yellow.download_dataset_task scheduled__2019-01-02T06:00:00+00:00 [running]> on host 6aa22590a839
[2022-02-06 22:46:20,790] {warnings.py:110} WARNING - /home/***/.local/lib/python3.7/site-packages/***/utils/context.py:152: AirflowContextDeprecationWarning: Accessing 'execution_date' from the template is deprecated and will be removed in a future version. Please use 'data_interval_start' or 'logical_date' instead.
  warnings.warn(_create_deprecation_warning(key, self._deprecation_replacements[key]))

[2022-02-06 22:46:21,135] {taskinstance.py:1426} INFO - Exporting the following env vars:
AIRFLOW_CTX_DAG_OWNER=***
AIRFLOW_CTX_DAG_ID=data_ingestion_gcs_dag_yellow
AIRFLOW_CTX_TASK_ID=download_dataset_task
AIRFLOW_CTX_EXECUTION_DATE=2019-01-02T06:00:00+00:00
AIRFLOW_CTX_DAG_RUN_ID=scheduled__2019-01-02T06:00:00+00:00
[2022-02-06 22:46:21,147] {subprocess.py:62} INFO - Tmp dir root location: 
 /tmp
[2022-02-06 22:46:21,152] {subprocess.py:74} INFO - Running command: ['bash', '-c', 'curl -sS https://s3.amazonaws.com/nyc-tlc/trip+data/yellow_tripdata_2019-01.csv > /opt/***/yellow_tripdata_2019-01.csv']
[2022-02-06 22:46:21,352] {subprocess.py:85} INFO - Output:
[2022-02-06 23:02:02,201] {base_job.py:230} ERROR - LocalTaskJob heartbeat got an exception
Traceback (most recent call last):
  File "/home/airflow/.local/lib/python3.7/site-packages/sqlalchemy/engine/base.py", line 2336, in _wrap_pool_connect
    return fn()
  File "/home/airflow/.local/lib/python3.7/site-packages/sqlalchemy/pool/base.py", line 364, in connect
    return _ConnectionFairy._checkout(self)
  File "/home/airflow/.local/lib/python3.7/site-packages/sqlalchemy/pool/base.py", line 778, in _checkout
    fairy = _ConnectionRecord.checkout(pool)
  File "/home/airflow/.local/lib/python3.7/site-packages/sqlalchemy/pool/base.py", line 495, in checkout
    rec = pool._do_get()
  File "/home/airflow/.local/lib/python3.7/site-packages/sqlalchemy/pool/impl.py", line 241, in _do_get
    return self._create_connection()
  File "/home/airflow/.local/lib/python3.7/site-packages/sqlalchemy/pool/base.py", line 309, in _create_connection
    return _ConnectionRecord(self)
  File "/home/airflow/.local/lib/python3.7/site-packages/sqlalchemy/pool/base.py", line 440, in __init__
    self.__connect(first_connect_check=True)
  File "/home/airflow/.local/lib/python3.7/site-packages/sqlalchemy/pool/base.py", line 661, in __connect
    pool.logger.debug("Error on connect(): %s", e)
  File "/home/airflow/.local/lib/python3.7/site-packages/sqlalchemy/util/langhelpers.py", line 70, in __exit__
    with_traceback=exc_tb,
  File "/home/airflow/.local/lib/python3.7/site-packages/sqlalchemy/util/compat.py", line 182, in raise_
    raise exception
  File "/home/airflow/.local/lib/python3.7/site-packages/sqlalchemy/pool/base.py", line 656, in __connect
    connection = pool._invoke_creator(self)
  File "/home/airflow/.local/lib/python3.7/site-packages/sqlalchemy/engine/strategies.py", line 114, in connect
    return dialect.connect(*cargs, **cparams)
  File "/home/airflow/.local/lib/python3.7/site-packages/sqlalchemy/engine/default.py", line 508, in connect
    return self.dbapi.connect(*cargs, **cparams)
  File "/home/airflow/.local/lib/python3.7/site-packages/psycopg2/__init__.py", line 122, in connect
    conn = _connect(dsn, connection_factory=connection_factory, **kwasync)
psycopg2.OperationalError: could not translate host name "postgres" to address: Temporary failure in name resolution


The above exception was the direct cause of the following exception:

Traceback (most recent call last):
  File "/home/airflow/.local/lib/python3.7/site-packages/airflow/jobs/base_job.py", line 220, in heartbeat
    session.merge(self)
  File "/home/airflow/.local/lib/python3.7/site-packages/sqlalchemy/orm/session.py", line 2171, in merge
    _resolve_conflict_map=_resolve_conflict_map,
  File "/home/airflow/.local/lib/python3.7/site-packages/sqlalchemy/orm/session.py", line 2244, in _merge
    merged = self.query(mapper.class_).get(key[1])
  File "/home/airflow/.local/lib/python3.7/site-packages/sqlalchemy/orm/query.py", line 1018, in get
    return self._get_impl(ident, loading.load_on_pk_identity)
  File "/home/airflow/.local/lib/python3.7/site-packages/sqlalchemy/orm/query.py", line 1135, in _get_impl
    return db_load_fn(self, primary_key_identity)
  File "/home/airflow/.local/lib/python3.7/site-packages/sqlalchemy/orm/loading.py", line 286, in load_on_pk_identity
    return q.one()
  File "/home/airflow/.local/lib/python3.7/site-packages/sqlalchemy/orm/query.py", line 3490, in one
    ret = self.one_or_none()
  File "/home/airflow/.local/lib/python3.7/site-packages/sqlalchemy/orm/query.py", line 3459, in one_or_none
    ret = list(self)
  File "/home/airflow/.local/lib/python3.7/site-packages/sqlalchemy/orm/query.py", line 3535, in __iter__
    return self._execute_and_instances(context)
  File "/home/airflow/.local/lib/python3.7/site-packages/sqlalchemy/orm/query.py", line 3557, in _execute_and_instances
    querycontext, self._connection_from_session, close_with_result=True
  File "/home/airflow/.local/lib/python3.7/site-packages/sqlalchemy/orm/query.py", line 3572, in _get_bind_args
    mapper=self._bind_mapper(), clause=querycontext.statement, **kw
  File "/home/airflow/.local/lib/python3.7/site-packages/sqlalchemy/orm/query.py", line 3550, in _connection_from_session
    conn = self.session.connection(**kw)
  File "/home/airflow/.local/lib/python3.7/site-packages/sqlalchemy/orm/session.py", line 1145, in connection
    execution_options=execution_options,
  File "/home/airflow/.local/lib/python3.7/site-packages/sqlalchemy/orm/session.py", line 1151, in _connection_for_bind
    engine, execution_options
  File "/home/airflow/.local/lib/python3.7/site-packages/sqlalchemy/orm/session.py", line 433, in _connection_for_bind
    conn = bind._contextual_connect()
  File "/home/airflow/.local/lib/python3.7/site-packages/sqlalchemy/engine/base.py", line 2302, in _contextual_connect
    self._wrap_pool_connect(self.pool.connect, None),
  File "/home/airflow/.local/lib/python3.7/site-packages/sqlalchemy/engine/base.py", line 2340, in _wrap_pool_connect
    e, dialect, self
  File "/home/airflow/.local/lib/python3.7/site-packages/sqlalchemy/engine/base.py", line 1584, in _handle_dbapi_exception_noconnection
    sqlalchemy_exception, with_traceback=exc_info[2], from_=e
  File "/home/airflow/.local/lib/python3.7/site-packages/sqlalchemy/util/compat.py", line 182, in raise_
    raise exception
  File "/home/airflow/.local/lib/python3.7/site-packages/sqlalchemy/engine/base.py", line 2336, in _wrap_pool_connect
    return fn()
  File "/home/airflow/.local/lib/python3.7/site-packages/sqlalchemy/pool/base.py", line 364, in connect
    return _ConnectionFairy._checkout(self)
  File "/home/airflow/.local/lib/python3.7/site-packages/sqlalchemy/pool/base.py", line 778, in _checkout
    fairy = _ConnectionRecord.checkout(pool)
  File "/home/airflow/.local/lib/python3.7/site-packages/sqlalchemy/pool/base.py", line 495, in checkout
    rec = pool._do_get()
  File "/home/airflow/.local/lib/python3.7/site-packages/sqlalchemy/pool/impl.py", line 241, in _do_get
    return self._create_connection()
  File "/home/airflow/.local/lib/python3.7/site-packages/sqlalchemy/pool/base.py", line 309, in _create_connection
    return _ConnectionRecord(self)
  File "/home/airflow/.local/lib/python3.7/site-packages/sqlalchemy/pool/base.py", line 440, in __init__
    self.__connect(first_connect_check=True)
  File "/home/airflow/.local/lib/python3.7/site-packages/sqlalchemy/pool/base.py", line 661, in __connect
    pool.logger.debug("Error on connect(): %s", e)
  File "/home/airflow/.local/lib/python3.7/site-packages/sqlalchemy/util/langhelpers.py", line 70, in __exit__
    with_traceback=exc_tb,
  File "/home/airflow/.local/lib/python3.7/site-packages/sqlalchemy/util/compat.py", line 182, in raise_
    raise exception
  File "/home/airflow/.local/lib/python3.7/site-packages/sqlalchemy/pool/base.py", line 656, in __connect
    connection = pool._invoke_creator(self)
  File "/home/airflow/.local/lib/python3.7/site-packages/sqlalchemy/engine/strategies.py", line 114, in connect
    return dialect.connect(*cargs, **cparams)
  File "/home/airflow/.local/lib/python3.7/site-packages/sqlalchemy/engine/default.py", line 508, in connect
    return self.dbapi.connect(*cargs, **cparams)
  File "/home/airflow/.local/lib/python3.7/site-packages/psycopg2/__init__.py", line 122, in connect
    conn = _connect(dsn, connection_factory=connection_factory, **kwasync)
sqlalchemy.exc.OperationalError: (psycopg2.OperationalError) could not translate host name "postgres" to address: Temporary failure in name resolution

(Background on this error at: http://sqlalche.me/e/13/e3q8)
[2022-02-06 23:10:21,747] {subprocess.py:93} INFO - Command exited with return code 0
[2022-02-06 23:12:35,605] {base_job.py:230} ERROR - LocalTaskJob heartbeat got an exception
Traceback (most recent call last):
  File "/home/airflow/.local/lib/python3.7/site-packages/sqlalchemy/engine/base.py", line 2336, in _wrap_pool_connect
    return fn()
  File "/home/airflow/.local/lib/python3.7/site-packages/sqlalchemy/pool/base.py", line 364, in connect
    return _ConnectionFairy._checkout(self)
  File "/home/airflow/.local/lib/python3.7/site-packages/sqlalchemy/pool/base.py", line 778, in _checkout
    fairy = _ConnectionRecord.checkout(pool)
  File "/home/airflow/.local/lib/python3.7/site-packages/sqlalchemy/pool/base.py", line 495, in checkout
    rec = pool._do_get()
  File "/home/airflow/.local/lib/python3.7/site-packages/sqlalchemy/pool/impl.py", line 241, in _do_get
    return self._create_connection()
  File "/home/airflow/.local/lib/python3.7/site-packages/sqlalchemy/pool/base.py", line 309, in _create_connection
    return _ConnectionRecord(self)
  File "/home/airflow/.local/lib/python3.7/site-packages/sqlalchemy/pool/base.py", line 440, in __init__
    self.__connect(first_connect_check=True)
  File "/home/airflow/.local/lib/python3.7/site-packages/sqlalchemy/pool/base.py", line 661, in __connect
    pool.logger.debug("Error on connect(): %s", e)
  File "/home/airflow/.local/lib/python3.7/site-packages/sqlalchemy/util/langhelpers.py", line 70, in __exit__
    with_traceback=exc_tb,
  File "/home/airflow/.local/lib/python3.7/site-packages/sqlalchemy/util/compat.py", line 182, in raise_
    raise exception
  File "/home/airflow/.local/lib/python3.7/site-packages/sqlalchemy/pool/base.py", line 656, in __connect
    connection = pool._invoke_creator(self)
  File "/home/airflow/.local/lib/python3.7/site-packages/sqlalchemy/engine/strategies.py", line 114, in connect
    return dialect.connect(*cargs, **cparams)
  File "/home/airflow/.local/lib/python3.7/site-packages/sqlalchemy/engine/default.py", line 508, in connect
    return self.dbapi.connect(*cargs, **cparams)
  File "/home/airflow/.local/lib/python3.7/site-packages/psycopg2/__init__.py", line 122, in connect
    conn = _connect(dsn, connection_factory=connection_factory, **kwasync)
psycopg2.OperationalError: connection to server at "postgres" (172.21.0.8), port 5432 failed: server closed the connection unexpectedly
	This probably means the server terminated abnormally
	before or while processing the request.


The above exception was the direct cause of the following exception:

Traceback (most recent call last):
  File "/home/airflow/.local/lib/python3.7/site-packages/airflow/jobs/base_job.py", line 226, in heartbeat
    self.heartbeat_callback(session=session)
  File "/home/airflow/.local/lib/python3.7/site-packages/airflow/utils/session.py", line 67, in wrapper
    return func(*args, **kwargs)
  File "/home/airflow/.local/lib/python3.7/site-packages/airflow/jobs/local_task_job.py", line 184, in heartbeat_callback
    self.task_instance.refresh_from_db()
  File "/home/airflow/.local/lib/python3.7/site-packages/airflow/utils/session.py", line 70, in wrapper
    return func(*args, session=session, **kwargs)
  File "/home/airflow/.local/lib/python3.7/site-packages/airflow/models/taskinstance.py", line 728, in refresh_from_db
    ti = qry.first()
  File "/home/airflow/.local/lib/python3.7/site-packages/sqlalchemy/orm/query.py", line 3429, in first
    ret = list(self[0:1])
  File "/home/airflow/.local/lib/python3.7/site-packages/sqlalchemy/orm/query.py", line 3203, in __getitem__
    return list(res)
  File "/home/airflow/.local/lib/python3.7/site-packages/sqlalchemy/orm/query.py", line 3535, in __iter__
    return self._execute_and_instances(context)
  File "/home/airflow/.local/lib/python3.7/site-packages/sqlalchemy/orm/query.py", line 3557, in _execute_and_instances
    querycontext, self._connection_from_session, close_with_result=True
  File "/home/airflow/.local/lib/python3.7/site-packages/sqlalchemy/orm/query.py", line 3572, in _get_bind_args
    mapper=self._bind_mapper(), clause=querycontext.statement, **kw
  File "/home/airflow/.local/lib/python3.7/site-packages/sqlalchemy/orm/query.py", line 3550, in _connection_from_session
    conn = self.session.connection(**kw)
  File "/home/airflow/.local/lib/python3.7/site-packages/sqlalchemy/orm/session.py", line 1145, in connection
    execution_options=execution_options,
  File "/home/airflow/.local/lib/python3.7/site-packages/sqlalchemy/orm/session.py", line 1151, in _connection_for_bind
    engine, execution_options
  File "/home/airflow/.local/lib/python3.7/site-packages/sqlalchemy/orm/session.py", line 433, in _connection_for_bind
    conn = bind._contextual_connect()
  File "/home/airflow/.local/lib/python3.7/site-packages/sqlalchemy/engine/base.py", line 2302, in _contextual_connect
    self._wrap_pool_connect(self.pool.connect, None),
  File "/home/airflow/.local/lib/python3.7/site-packages/sqlalchemy/engine/base.py", line 2340, in _wrap_pool_connect
    e, dialect, self
  File "/home/airflow/.local/lib/python3.7/site-packages/sqlalchemy/engine/base.py", line 1584, in _handle_dbapi_exception_noconnection
    sqlalchemy_exception, with_traceback=exc_info[2], from_=e
  File "/home/airflow/.local/lib/python3.7/site-packages/sqlalchemy/util/compat.py", line 182, in raise_
    raise exception
  File "/home/airflow/.local/lib/python3.7/site-packages/sqlalchemy/engine/base.py", line 2336, in _wrap_pool_connect
    return fn()
  File "/home/airflow/.local/lib/python3.7/site-packages/sqlalchemy/pool/base.py", line 364, in connect
    return _ConnectionFairy._checkout(self)
  File "/home/airflow/.local/lib/python3.7/site-packages/sqlalchemy/pool/base.py", line 778, in _checkout
    fairy = _ConnectionRecord.checkout(pool)
  File "/home/airflow/.local/lib/python3.7/site-packages/sqlalchemy/pool/base.py", line 495, in checkout
    rec = pool._do_get()
  File "/home/airflow/.local/lib/python3.7/site-packages/sqlalchemy/pool/impl.py", line 241, in _do_get
    return self._create_connection()
  File "/home/airflow/.local/lib/python3.7/site-packages/sqlalchemy/pool/base.py", line 309, in _create_connection
    return _ConnectionRecord(self)
  File "/home/airflow/.local/lib/python3.7/site-packages/sqlalchemy/pool/base.py", line 440, in __init__
    self.__connect(first_connect_check=True)
  File "/home/airflow/.local/lib/python3.7/site-packages/sqlalchemy/pool/base.py", line 661, in __connect
    pool.logger.debug("Error on connect(): %s", e)
  File "/home/airflow/.local/lib/python3.7/site-packages/sqlalchemy/util/langhelpers.py", line 70, in __exit__
    with_traceback=exc_tb,
  File "/home/airflow/.local/lib/python3.7/site-packages/sqlalchemy/util/compat.py", line 182, in raise_
    raise exception
  File "/home/airflow/.local/lib/python3.7/site-packages/sqlalchemy/pool/base.py", line 656, in __connect
    connection = pool._invoke_creator(self)
  File "/home/airflow/.local/lib/python3.7/site-packages/sqlalchemy/engine/strategies.py", line 114, in connect
    return dialect.connect(*cargs, **cparams)
  File "/home/airflow/.local/lib/python3.7/site-packages/sqlalchemy/engine/default.py", line 508, in connect
    return self.dbapi.connect(*cargs, **cparams)
  File "/home/airflow/.local/lib/python3.7/site-packages/psycopg2/__init__.py", line 122, in connect
    conn = _connect(dsn, connection_factory=connection_factory, **kwasync)
sqlalchemy.exc.OperationalError: (psycopg2.OperationalError) connection to server at "postgres" (172.21.0.8), port 5432 failed: server closed the connection unexpectedly
	This probably means the server terminated abnormally
	before or while processing the request.

(Background on this error at: http://sqlalche.me/e/13/e3q8)
[2022-02-06 23:19:01,534] {taskinstance.py:1277} INFO - Marking task as SUCCESS. dag_id=data_ingestion_gcs_dag_yellow, task_id=download_dataset_task, execution_date=20190102T060000, start_date=20220206T224618, end_date=20220206T231856
