[2022-02-06 11:21:36,378] {taskinstance.py:1032} INFO - Dependencies all met for <TaskInstance: data_ingestion_gcs_dag.download_dataset_task scheduled__2020-09-02T06:00:00+00:00 [queued]>
[2022-02-06 11:21:36,518] {taskinstance.py:1032} INFO - Dependencies all met for <TaskInstance: data_ingestion_gcs_dag.download_dataset_task scheduled__2020-09-02T06:00:00+00:00 [queued]>
[2022-02-06 11:21:36,520] {taskinstance.py:1238} INFO - 
--------------------------------------------------------------------------------
[2022-02-06 11:21:36,524] {taskinstance.py:1239} INFO - Starting attempt 1 of 2
[2022-02-06 11:21:36,529] {taskinstance.py:1240} INFO - 
--------------------------------------------------------------------------------
[2022-02-06 11:21:36,675] {taskinstance.py:1259} INFO - Executing <Task(BashOperator): download_dataset_task> on 2020-09-02 06:00:00+00:00
[2022-02-06 11:21:36,757] {standard_task_runner.py:52} INFO - Started process 2696 to run task
[2022-02-06 11:21:36,852] {standard_task_runner.py:76} INFO - Running: ['***', 'tasks', 'run', 'data_ingestion_gcs_dag', 'download_dataset_task', 'scheduled__2020-09-02T06:00:00+00:00', '--job-id', '137', '--raw', '--subdir', 'DAGS_FOLDER/data_ingestion_gcs_dags_hw.py', '--cfg-path', '/tmp/tmpzo8h34vp', '--error-file', '/tmp/tmp6p16xcm_']
[2022-02-06 11:21:36,916] {standard_task_runner.py:77} INFO - Job 137: Subtask download_dataset_task
[2022-02-06 11:21:38,111] {logging_mixin.py:109} INFO - Running <TaskInstance: data_ingestion_gcs_dag.download_dataset_task scheduled__2020-09-02T06:00:00+00:00 [running]> on host 6aa22590a839
[2022-02-06 11:21:38,357] {warnings.py:110} WARNING - /home/***/.local/lib/python3.7/site-packages/***/utils/context.py:152: AirflowContextDeprecationWarning: Accessing 'execution_date' from the template is deprecated and will be removed in a future version. Please use 'data_interval_start' or 'logical_date' instead.
  warnings.warn(_create_deprecation_warning(key, self._deprecation_replacements[key]))

[2022-02-06 11:21:38,450] {taskinstance.py:1426} INFO - Exporting the following env vars:
AIRFLOW_CTX_DAG_OWNER=***
AIRFLOW_CTX_DAG_ID=data_ingestion_gcs_dag
AIRFLOW_CTX_TASK_ID=download_dataset_task
AIRFLOW_CTX_EXECUTION_DATE=2020-09-02T06:00:00+00:00
AIRFLOW_CTX_DAG_RUN_ID=scheduled__2020-09-02T06:00:00+00:00
[2022-02-06 11:21:38,455] {subprocess.py:62} INFO - Tmp dir root location: 
 /tmp
[2022-02-06 11:21:38,462] {subprocess.py:74} INFO - Running command: ['bash', '-c', 'curl -sS https://s3.amazonaws.com/nyc-tlc/trip+data/yellow_tripdata_2020-09.csv > /opt/***/yellow_tripdata_2020-09.csv']
[2022-02-06 11:21:38,583] {subprocess.py:85} INFO - Output:
[2022-02-06 14:59:36,938] {local_task_job.py:212} WARNING - State of this instance has been externally set to up_for_retry. Terminating instance.
[2022-02-06 14:59:37,070] {process_utils.py:124} INFO - Sending Signals.SIGTERM to group 2696. PIDs of all processes in the group: [2698, 2699, 2696]
[2022-02-06 14:59:37,077] {process_utils.py:75} INFO - Sending the signal Signals.SIGTERM to group 2696
[2022-02-06 14:59:37,111] {taskinstance.py:1408} ERROR - Received SIGTERM. Terminating subprocesses.
[2022-02-06 14:59:37,192] {subprocess.py:99} INFO - Sending SIGTERM signal to process group
[2022-02-06 14:59:37,255] {process_utils.py:70} INFO - Process psutil.Process(pid=2699, status='terminated', started='11:21:38') (2699) terminated with exit code None
[2022-02-06 14:59:37,791] {taskinstance.py:1700} ERROR - Task failed with exception
Traceback (most recent call last):
  File "/home/airflow/.local/lib/python3.7/site-packages/airflow/models/taskinstance.py", line 1329, in _run_raw_task
    self._execute_task_with_callbacks(context)
  File "/home/airflow/.local/lib/python3.7/site-packages/airflow/models/taskinstance.py", line 1455, in _execute_task_with_callbacks
    result = self._execute_task(context, self.task)
  File "/home/airflow/.local/lib/python3.7/site-packages/airflow/models/taskinstance.py", line 1511, in _execute_task
    result = execute_callable(context=context)
  File "/home/airflow/.local/lib/python3.7/site-packages/airflow/operators/bash.py", line 182, in execute
    cwd=self.cwd,
  File "/home/airflow/.local/lib/python3.7/site-packages/airflow/hooks/subprocess.py", line 87, in run_command
    for raw_line in iter(self.sub_process.stdout.readline, b''):
  File "/home/airflow/.local/lib/python3.7/site-packages/airflow/models/taskinstance.py", line 1410, in signal_handler
    raise AirflowException("Task received SIGTERM signal")
airflow.exceptions.AirflowException: Task received SIGTERM signal
[2022-02-06 14:59:37,925] {taskinstance.py:1277} INFO - Marking task as FAILED. dag_id=data_ingestion_gcs_dag, task_id=download_dataset_task, execution_date=20200902T060000, start_date=20220206T112136, end_date=20220206T145937
[2022-02-06 14:59:38,300] {standard_task_runner.py:92} ERROR - Failed to execute job 137 for task download_dataset_task
Traceback (most recent call last):
  File "/home/airflow/.local/lib/python3.7/site-packages/airflow/task/task_runner/standard_task_runner.py", line 85, in _start_by_fork
    args.func(args, dag=self.dag)
  File "/home/airflow/.local/lib/python3.7/site-packages/airflow/cli/cli_parser.py", line 48, in command
    return func(*args, **kwargs)
  File "/home/airflow/.local/lib/python3.7/site-packages/airflow/utils/cli.py", line 92, in wrapper
    return f(*args, **kwargs)
  File "/home/airflow/.local/lib/python3.7/site-packages/airflow/cli/commands/task_command.py", line 298, in task_run
    _run_task_by_selected_method(args, dag, ti)
  File "/home/airflow/.local/lib/python3.7/site-packages/airflow/cli/commands/task_command.py", line 107, in _run_task_by_selected_method
    _run_raw_task(args, ti)
  File "/home/airflow/.local/lib/python3.7/site-packages/airflow/cli/commands/task_command.py", line 184, in _run_raw_task
    error_file=args.error_file,
  File "/home/airflow/.local/lib/python3.7/site-packages/airflow/utils/session.py", line 70, in wrapper
    return func(*args, session=session, **kwargs)
  File "/home/airflow/.local/lib/python3.7/site-packages/airflow/models/taskinstance.py", line 1329, in _run_raw_task
    self._execute_task_with_callbacks(context)
  File "/home/airflow/.local/lib/python3.7/site-packages/airflow/models/taskinstance.py", line 1455, in _execute_task_with_callbacks
    result = self._execute_task(context, self.task)
  File "/home/airflow/.local/lib/python3.7/site-packages/airflow/models/taskinstance.py", line 1511, in _execute_task
    result = execute_callable(context=context)
  File "/home/airflow/.local/lib/python3.7/site-packages/airflow/operators/bash.py", line 182, in execute
    cwd=self.cwd,
  File "/home/airflow/.local/lib/python3.7/site-packages/airflow/hooks/subprocess.py", line 87, in run_command
    for raw_line in iter(self.sub_process.stdout.readline, b''):
  File "/home/airflow/.local/lib/python3.7/site-packages/airflow/models/taskinstance.py", line 1410, in signal_handler
    raise AirflowException("Task received SIGTERM signal")
airflow.exceptions.AirflowException: Task received SIGTERM signal
[2022-02-06 14:59:38,695] {process_utils.py:70} INFO - Process psutil.Process(pid=2698, status='terminated', started='11:21:38') (2698) terminated with exit code None
[2022-02-06 14:59:38,699] {process_utils.py:70} INFO - Process psutil.Process(pid=2696, status='terminated', exitcode=1, started='11:21:36') (2696) terminated with exit code 1
